Workbook

Sheet Listas
A2: Albertina Tumba | B2: Proposta enviada | D2: A
A3: Amélia Cassinda | B3: Proposta em negociação | D3: B
A4: David Guedes | B4: Proposta aprovada | D4: C
A5: Elizabete Miguel | B5: Perdida
A6: Luísa Baltazar | B6: Produção / Entrega
A7: Marta de Oliveira
A8: Regina Pompilho

Sheet Capa
A1: GPA ANGOLA CRM COMERCIAL COMPLETO
A5: Pipeline, KPIs, dashboard, instruções de registo e análise comercial automática
A8: 1. PIPELINE Registo integral das propostas, responsáveis, datas, probabilidade, prioridade e valor ponderado. | E8: 2. KPI COMERCIAL Taxas de conversão, ticket médio, negócios aprovados, contactos da semana e ranking por comercial.
A14: 3. DASHBOARD Gráficos automáticos, leitura executiva e indicadores de controlo. | E14: 4. INSTRUÇÕES CRM Normas de preenchimento, cadência de follow-up e responsabilidades comerciais.
A21: Fonte base: relatório consolidado de clientes de 01 a 30 de Junho de 2026. O ficheiro inclui fórmulas automáticas, validações de dados e gráficos prontos para gestão comercial.

Sheet Instruções_CRM
B1: INSTRUÇÕES DE REGISTO NO CRM
B4: 1. Objectivo | C4: Registar todas as oportunidades comerciais com rigor, permitindo controlo do pipeline, previsibilidade de fecho e responsabilização individual.
B5: 2. Quando registar | C5: Toda a proposta deve ser lançada no próprio dia do envio ao cliente. Cada novo contacto, negociação, alteração de probabilidade ou aprovação deve actualizar imediatamente a linha correspondente.
B6: 3. Campos obrigatórios | C6: Data de envio, cliente, serviço, estado da proposta, valor, probabilidade, gestor comercial, próxima acção, próximo contacto e observações objectivas.
B7: 4. Regras de probabilidade | C7: 40% = proposta enviada sem validação; 50% = proposta acompanhada; 60% = cliente em análise activa; 75% = negociação final; 100% = aprovado / adjudicado.
B8: 5. Regra de follow-up | C8: Nenhuma proposta pode ficar apenas com a nota 'aguardamos feedback'. Deve sempre existir próxima acção concreta e data específica de contacto.
B9: 6. Classe do cliente | C9: Classe A = conta estratégica / grande volume; Classe B = cliente recorrente; Classe C = cliente ocasional ou pequeno ticket.
B10: 7. Prioridade | C10: Alta = negócios ≥ 50.000.000 Kz ou probabilidade ≥ 75%; Média = negócios ≥ 5.000.000 Kz ou probabilidade ≥ 50%; Normal = restantes casos.
B11: 8. Estado CRM | C11: Aberto = proposta enviada ou em negociação; Fechado ganho = aprovado / produção; Fechado perdido = perdida.
B12: 9. Responsabilidade do comercial | C12: Cada gestor responde pela actualização semanal da sua carteira, qualidade da informação, precisão da probabilidade e fecho dos dossiers sob sua gestão.
B13: 10. Observação de controlo | C13: O relatório de origem apresenta divergência entre o número de pedidos declarado (31) e o total de linhas individuais detectadas (33). O CRM regista as 33 linhas visíveis para garantir rastreabilidade.

Sheet Pipeline
A1: ID | B1: Data envio | C1: Cliente | D1: Serviço | E1: Estado proposta | F1: Valor proposta | G1: Valor aprovado | H1: Valor perdido | I1: Probabilidade | J1: Gestor comercial | K1: Próxima acção | L1: Próximo contacto | M1: Observações | N1: Dias em aberto | O1: Valor ponderado | P1: Classe cliente | Q1: Prioridade | R1: Estado CRM
A2: 1 | B2: 46204 | C2: COSCAL LIMITADA | D2: Brindes e Materiais de Merchandising | E2: Proposta aprovada | F2: 2755950 | G2: 2755950 | H2: 0 | I2: 1 | J2: Luísa Baltazar | K2: Manter o cliente por perto para obter mais trabalhos | L2: 46240 | M2: Material produzido e entregue com feedback positivo | N2: =IF(B2="","",TODAY()-B2) -> 35 | O2: =F2*I2 -> 2755950 | P2: C | Q2: =IF(OR(F2>=50000000,I2>=0.75),"Alta",IF(OR(F2>=5000000,I2>=0.5),"Média","Normal")) -> Alta | R2: =IF(E2="Proposta aprovada","Fechado ganho",IF(E2="Perdida","Fechado perdido","Aberto")) -> Fechado ganho
A3: 2 | B3: 46213 | C3: COSCAL LIMITADA | D3: Impressão de Flyers | E3: Proposta aprovada | F3: 313500 | G3: 313500 | H3: 0 | I3: 1 | J3: Luísa Baltazar | K3: Manter o cliente por perto para obter mais trabalhos | L3: 46240 | M3: Material produzido e entregue com feedback positivo | N3: =IF(B3="","",TODAY()-B3) -> 26 | O3: =F3*I3 -> 313500 | P3: C | Q3: =IF(OR(F3>=50000000,I3>=0.75),"Alta",IF(OR(F3>=5000000,I3>=0.5),"Média","Normal")) -> Alta | R3: =IF(E3="Proposta aprovada","Fechado ganho",IF(E3="Perdida","Fechado perdido","Aberto")) -> Fechado ganho
A4: 3 | B4: 46211 | C4: ALIANÇA SEGUROS | D4: Impressão de Flyers | E4: Perdida | F4: 3328800 | G4: 0 | H4: 3328800 | I4: 0 | J4: Luísa Baltazar | K4: Focar em outros processos | L4: 46240 | M4: O cliente não especificou o motivo da rejeição | N4: =IF(B4="","",TODAY()-B4) -> 28 | O4: =F4*IB+O4 -> 0 | P4: B | Q4: =IF(OR(F4>=50000000,I4>=0.75),"Alta",IF(OR(F4>=5000000,I4>=0.5),"Média","Normal")) -> Normal | R4: =IF(E4="Proposta aprovada","Fechado ganho",IF(E4="Perdida","Fechado perdido","Aberto")) -> Fechado perdido
A5: 4 | B5: 46204 | C5: FINSTAR | D5: T-Shirts para Lojistas | E5: Proposta aprovada | F5: 21161250 | G5: 21161250 | H5: 0 | I5: 1 | J5: Luísa Baltazar | K5: Pressionar a informação relativamente aos tamanhos para dar início a produção | L5: 46240 | M5: O cliente já partilhou as artes, mas ainda temos em falta os tamanhos | N5: =IF(B5="","",TODAY()-B5) -> 35 | O5: =F5*I5 -> 21161250 | P5: A | Q5: =IF(OR(F5>=50000000,I5>=0.75),"Alta",IF(OR(F5>=5000000,I5>=0.5),"Média","Normal")) -> Alta | R5: =IF(E5="Proposta aprovada","Fechado ganho",IF(E5="Perdida","Fechado perdido","Aberto")) -> Fechado ganho
A6: 5 | B6: 46218 | C6: FINSTAR | D6: T-Shirts para Lojistas (2ª Fase) | E6: Proposta em negociação | F6: 21161250 | G6: 0 | H6: 0 | I6: 0.6 | J6: Luísa Baltazar | K6: Pressionar o envio da PO | L6: 46240 | M6: A PO está em processamento | N6: =IF(B6="","",TODAY()-B6) -> 21 | O6: =F6*I6 -> 12696750 | P6: A | Q6: =IF(OR(F6>=50000000,I6>=0.75),"Alta",IF(OR(F6>=5000000,I6>=0.5),"Média","Normal")) -> Média | R6: =IF(E6="Proposta aprovada","Fechado ganho",IF(E6="Perdida","Fechado perdido","Aberto")) -> Aberto
A7: 6 | B7: 46218 | C7: FINSTAR | D7: Sacos TNT | E7: Proposta aprovada | F7: 1687200 | G7: 1687200 | H7: 0 | I7: 1 | J7: Luísa Baltazar | K7: Manter o contacto com o cliente para obter novas aprovações | L7: 46240 | M7: Material produzido e entregue | N7: =IF(B7="","",TODAY()-B7) -> 21 | O7: =F7*I7 -> 1687200 | P7: A | Q7: =IF(OR(F7>=50000000,I7>=0.75),"Alta",IF(OR(F7>=5000000,I7>=0.5),"Média","Normal")) -> Alta | R7: =IF(E7="Proposta aprovada","Fechado ganho",IF(E7="Perdida","Fechado perdido","Aberto")) -> Fechado ganho
A8: 7 | B8: 46223 | C8: FINSTAR | D8: Materiais Diversos | E8: Perdida | F8: 1508220 | G8: 0 | H8: 1508220 | I8: 0 | J8: Luísa Baltazar | K8: Focar em outros processos | L8: 46240 | M8: O cliente optou por avançar com o fornecedor onde tinham saldo pendente | N8: =IF(B8="","",TODAY()-B8) -> 16 | O8: =F8*I8 -> 0 | P8: A | Q8: =IF(OR(F8>=50000000,I8>=0.75),"Alta",IF(OR(F8>=5000000,I8>=0.5),"Média","Normal")) -> Normal | R8: =IF(E8="Proposta aprovada","Fechado ganho",IF(E8="Perdida","Fechado perdido","Aberto")) -> Fechado perdido
A9: 8 | B9: 46231 | C9: FINSTAR | D9: Fitas Porta Passe Sem Personalização | E9: Proposta aprovada | F9: 79800 | G9: 79800 | H9: 0 | I9: 1 | J9: Luísa Baltazar | K9: Negocias as restantes propostas em aberto | L9: 46240 | M9: O material já foi entregue | N9: =IF(B9="","",TODAY()-B9) -> 8 | O9: =F9*I9 -> 79800 | P9: A | Q9: =IF(OR(F9>=50000000,I9>=0.75),"Alta",IF(OR(F9>=5000000,I9>=0.5),"Média","Normal")) -> Alta | R9: =IF(E9="Proposta aprovada","Fechado ganho",IF(E9="Perdida","Fechado perdido","Aberto")) -> Fechado ganho
A10: 9 | B10: 46212 | C10: IMOCASAIS | D10: Fornecimento de Blocos de nota, canetas Flyers | E10: Perdida | F10: 1385100 | H10: 1385100 | I10: 0 | J10: Luísa Baltazar | K10: Focar em outros processos | L10: 46240 | M10: Devido ao preço, o cliente optou por avançar com outro fornecedor | N10: =IF(B10="","",TODAY()-B10) -> 27 | O10: =F10*I10 -> 0 | P10: C | Q10: =IF(OR(F10>=50000000,I10>=0.75),"Alta",IF(OR(F10>=5000000,I10>=0.5),"Média","Normal")) -> Normal | R10: =IF(E10="Proposta aprovada","Fechado ganho",IF(E10="Perdida","Fechado perdido","Aberto")) -> Fechado perdido
A11: 10 | B11: 46210 | C11: SUEZ | D11: Fornecimento de Flyrs monofolha e tripticos | E11: Proposta em negociação | F11: 6260880 | H11: 0 | I11: 0.5 | J11: Luísa Baltazar | K11: Negociar a modadlidade de pagamento | L11: 46240 | M11: Aguardamos o envio da PO | N11: =IF(B11="","",TODAY()-B11) -> 29 | O11: =F11*I11 -> 3130440 | P11: B | Q11: =IF(OR(F11>=50000000,I11>=0.75),"Alta",IF(OR(F11>=5000000,I11>=0.5),"Média","Normal")) -> Média | R11: =IF(E11="Proposta aprovada","Fechado ganho",IF(E11="Perdida","Fechado perdido","Aberto")) -> Aberto
A12: 11 | B12: 46209 | C12: TEIXERA DUARTE | D12: Fornecimento de Diversos | E12: Proposta aprovada | F12: 758100 | G12: 758100 | H12: 0 | I12: 1 | J12: Luísa Baltazar | K12: Aumentar o fluxo de trabalhos com este cliente | L12: 46240 | M12: Material produzido e entregue | N12: =IF(B12="","",TODAY()-B12) -> 30 | O12: =F12*I12 -> 758100 | P12: B | Q12: =IF(OR(F12>=50000000,I12>=0.75),"Alta",IF(OR(F12>=5000000,I12>=0.5),"Média","Normal")) -> Alta | R12: =IF(E12="Proposta aprovada","Fechado ganho",IF(E12="Perdida","Fechado perdido","Aberto")) -> Fechado ganho
A13: 12 | B13: 46210 | C13: SIAC | D13: Fornecimento de brindes e merchandising | E13: Proposta enviada | F13: 19418760 | G13: 0 | H13: 0 | I13: 0.4 | J13: Luísa Baltazar | K13: Agendar uma reunião com o cliente | L13: 46240 | M13: A nossa proposta está em análise | N13: =IF(B13="","",TODAY()-B13) -> 29 | O13: =F13*I13 -> 7767504 | P13: C | Q13: =IF(OR(F13>=50000000,I13>=0.75),"Alta",IF(OR(F13>=5000000,I13>=0.5),"Média","Normal")) -> Média | R13: =IF(E13="Proposta aprovada","Fechado ganho",IF(E13="Perdida","Fechado perdido","Aberto")) -> Aberto
A14: 13 | B14: 46189 | C14: ENDIAMA | D14: Fornecimento de materiais para outubro rosa | E14: Proposta em negociação | F14: 6958560 | H14: 0 | I14: 0.6 | J14: Luísa Baltazar | K14: Negociar a modadlidade de pagamento | L14: 46240 | M14: Falta o envio da PO, para credibilizar a adjudicação do processo | N14: =IF(B14="","",TODAY()-B14) -> 50 | O14: =F14*I14 -> 4175136 | P14: B | Q14: =IF(OR(F14>=50000000,I14>=0.75),"Alta",IF(OR(F14>=5000000,I14>=0.5),"Média","Normal")) -> Média | R14: =IF(E14="Proposta aprovada","Fechado ganho",IF(E14="Perdida","Fechado perdido","Aberto")) -> Aberto
A15: 14 | B15: 46216 | C15: UNITEL | D15: Canecas de Porcelana e Garrafas Térmica | E15: Proposta enviada | F15: 96124800 | G15: 0 | H15: 0 | I15: 0.4 | J15: Luísa Baltazar | K15: Incentivar o cliente para o envio da contraproposta. | L15: 46240 | M15: O processo de análise das propostas está em curso | N15: =IF(B15="","",MAX(0,TODAY()-B15)) -> 23 | O15: =IF(OR(F15="",I15=""),"",F15*I15) -> 38449920 | P15: A | Q15: Alta | R15: Aberto
A16: 15 | B16: 46218 | C16: CARPINANGOLA/CASAIS | D16: Bloco de Notas e Canetas | E16: Proposta aprovada | F16: 2017800 | G16: 2017800 | H16: 0 | I16: 1 | J16: Luísa Baltazar | K16: Alinhamento com a cliente para obter mais trabalhos | L16: 46240 | M16: O processo de produção está em curso, faremos a entrega no dia 20 de Julho | N16: =IF(B16="","",MAX(0,TODAY()-B16)) -> 21 | O16: =IF(OR(F16="",I16=""),"",F16*I16) -> 2017800 | P16: B | Q16: Alta | R16: Fechado ganho
A17: 16 | B17: 46220 | C17: CEGID/PRIMAVERA | D17: Impressão de Flyers | E17: Proposta aprovada | F17: 445700 | G17: 445700 | H17: 0 | I17: 1 | J17: Luísa Baltazar | K17: Cumprimento do prazo de entrega | L17: 46240 | M17: O processo de produção está em curso, faremos a entrega no dia 20 de Julho | N17: =IF(B17="","",MAX(0,TODAY()-B17)) -> 19 | O17: =IF(OR(F17="",I17=""),"",F17*I17) -> 445700 | P17: B | Q17: Alta | R17: Fechado ganho
A18: 17 | B18: 46220 | C18: FINSTAR/ZAP | D18: T-Shirts para Filda | E18: Proposta enviada | F18: 1966500 | G18: 0 | H18: 0 | I18: 0.5 | J18: Luísa Baltazar | K18: Persuadir a aprovação usando o prazo de entrega do estratégia | L18: 46240 | M18: As propostas ainda estão a ser analisadas | N18: =IF(B18="","",MAX(0,TODAY()-B18)) -> 19 | O18: =IF(OR(F18="",I18=""),"",F18*I18) -> 983250 | P18: A | Q18: Normal | R18: Aberto
A19: 18 | B19: 46219 | C19: SIAC | D19: Totens em Betão | E19: Proposta enviada | F19: 29641900 | G19: 0 | H19: 0 | I19: 0.4 | J19: Luísa Baltazar | K19: Solicitar uma reunião com este cliente | L19: 46240 | M19: A nossa proposta foi submetida para avaliação | N19: =IF(B19="","",MAX(0,TODAY()-B19)) -> 20 | O19: =IF(OR(F19="",I19=""),"",F19*I19) -> 11856760 | P19: C | Q19: Normal | R19: Aberto
A20: 19 | B20: 46234 | C20: ENDIAMA | D20: Tapete para Sala de Espera | E20: Proposta enviada | F20: 21906076 | G20: 0 | H20: 0 | I20: 0.4 | J20: Luísa Baltazar | K20: Apresentar uma proposta com maaterial mais econ | L20: 46240 | M20: O processo de análise das propostas está em curso | N20: =IF(B20="","",MAX(0,TODAY()-B20)) -> 5 | O20: =IF(OR(F20="",I20=""),"",F20*I20) -> 8762430.3 | P20: A | Q20: Alta | R20: Aberto
A21: 20 | B21: 46230 | C21: UNITEL | D21: Fitas Porta Passe | E21: Proposta enviada | F21: 21366450 | G21: 0 | H21: 0 | I21: 0.2 | J21: Luísa Baltazar | K21: Focar em outros processos | L21: 46240 | M21: A contraproposta apresentada pelo cliente está muito abaixo do nosso orçamento e não compensa avançar | N21: =IF(B21="","",MAX(0,TODAY()-B21)) -> 9 | O21: =IF(OR(F21="",I21=""),"",F21*I21) -> 4273290 | P21: A | Q21: Média | R21: Aberto
A22: 21 | B22: 46230 | C22: UNITEL | D22: Capas de Importação | E22: Proposta enviada | F22: 1303020 | G22: 0 | H22: 0 | I22: 0.2 | J22: Luísa Baltazar | K22: Focar em outros processos | L22: 46240 | M22: A contraproposta apresentada pelo cliente está muito abaixo do nosso orçamento e não compensa avançar | N22: =IF(B22="","",MAX(0,TODAY()-B22)) -> 9 | O22: =IF(OR(F22="",I22=""),"",F22*I22) -> 260604 | P22: A | Q22: Alta | R22: Aberto
A23: 22 | B23: 46233 | C23: FINSTAR/ZAP | D23: Letras Recortadas em PVC com Vinil | E23: Proposta enviada | F23: 628995 | G23: 0 | H23: 0 | I23: 0.5 | J23: Luísa Baltazar | K23: Contactar o cliente para pressionar a aprovação | L23: 46240 | M23: A nossa proposta está a ser analisada pelo cliente | N23: =IF(B23="","",MAX(0,TODAY()-B23)) -> 6 | O23: =IF(OR(F23="",I23=""),"",F23*I23) -> 314497.5 | P23: A | Q23: Alta | R23: Fechado ganho
A24: 23 | B24: 46234 | C24: CEGID | D24: Brindes e Materiais de Merchandising | E24: Proposta enviada | F24: 25891680 | G24: 0 | H24: 0 | I24: 0.2 | J24: Luísa Baltazar | K24: Focar em outros processos | L24: 46240 | M24: O nosso concorrente é internacional e a nossa proposta está o dobro do valor | N24: =IF(B24="","",MAX(0,TODAY()-B24)) -> 5 | O24: =IF(OR(F24="",I24=""),"",F24*I24) -> 5178336 | P24: B | Q24: Normal | R24: Aberto
A25: 24 | B25: 46223 | C25: SBM OFFSHORE | D25: Posters em Papel Satim | E25: Proposta aprovada | F25: 940500 | G25: 940500 | H25: 0 | I25: 1 | J25: Luísa Baltazar | K25: Produzir e entregar uma nova amostra ao cliente | L25: 46240 | M25: A amostra anteriormente produzida foi reprovada pelo cliente devido a qualidade de impressão | N25: =IF(B25="","",MAX(0,TODAY()-B25)) -> 16 | O25: =IF(OR(F25="",I25=""),"",F25*I25) -> 940500 | P25: A | Q25: Alta | R25: Aberto
A26: 25 | B26: 46226 | C26: ENDIAMA | D26: Criação e Impressão de Revistas | E26: Proposta enviada | F26: 6433020 | G26: 0 | H26: 0 | I26: 0.4 | J26: Luísa Baltazar | K26: Considerar a possibilidade de apresentar um desconto | L26: 46240 | M26: A nossa proposta está acima do orçamento apresentado pelo cliente | N26: =IF(B26="","",MAX(0,TODAY()-B26)) -> 13 | O26: =IF(OR(F26="",I26=""),"",F26*I26) -> 2573208 | P26: B | Q26: Alta | R26: Aberto
A27: 26 | B27: 46198 | C27: PAY4ALL | D27: Fornecimento de Brindes para a filda | E27: Proposta aprovada | F27: 2106150 | G27: 2106150 | H27: 0 | I27: 1 | J27: Amélia Cassinda | K27: Manter o contacto com o cliente para obter novas aprovações | L27: 46240 | M27: Material produzido e entregue | N27: =IF(B27="","",TODAY()-B27) -> 41 | O27: =F27*I27 -> 2106150 | P27: C | Q27: =IF(OR(F27>=50000000,I27>=0.75),"Alta",IF(OR(F27>=5000000,I27>=0.5),"Média","Normal")) -> Alta | R27: =IF(E27="Proposta aprovada","Fechado ganho",IF(E27="Perdida","Fechado perdido","Aberto")) -> Fechado ganho
A28: 27 | B28: 46209 | C28: XPRINT | D28: Fornecimento de Brindes e Têxtil | E28: Proposta enviada | F28: 2350680 | G28: 0 | H28: 0 | I28: 0.4 | J28: Amélia Cassinda | K28: Considerar a possibilidade de apresentar um desconto | L28: 46240 | M28: Proposta remetida para avaliação | N28: =IF(B28="","",TODAY()-B28) -> 30 | O28: =F28*I28 -> 940272 | P28: B | Q28: =IF(OR(F28>=50000000,I28>=0.75),"Alta",IF(OR(F28>=5000000,I28>=0.5),"Média","Normal")) -> Normal | R28: =IF(E28="Proposta aprovada","Fechado ganho",IF(E28="Perdida","Fechado perdido","Aberto")) -> Aberto
A29: 28 | B29: 46213 | C29: DUBAI INVESTIMETS | D29: Forneciemnto de Brindes | E29: Proposta enviada | F29: 6156000 | G29: 0 | H29: 0 | I29: 0.5 | J29: Amélia Cassinda | K29: Apresentar amostras Físicas e acompanhar o processo | L29: 46240 | M29: Proposta remetida para avaliação | N29: =IF(B29="","",TODAY()-B29) -> 26 | O29: =F29*I29 -> 3078000 | P29: C | Q29: =IF(OR(F29>=50000000,I29>=0.75),"Alta",IF(OR(F29>=5000000,I29>=0.5),"Média","Normal")) -> Média | R29: =IF(E29="Proposta aprovada","Fechado ganho",IF(E29="Perdida","Fechado perdido","Aberto")) -> Aberto
A30: 29 | B30: 46211 | C30: DUBAI INVESTIMETS | D30: Fornecimento de Flyrs | E30: Proposta enviada | F30: 3249000 | H30: 0 | I30: 0.4 | J30: Amélia Cassinda | K30: Apresentar amostras Físicas e acompanhar o processo | L30: 46240 | M30: Proposta remetida para avaliação | N30: =IF(B30="","",TODAY()-B30) -> 28 | O30: =F30*I30 -> 1299600 | P30: C | Q30: =IF(OR(F30>=50000000,I30>=0.75),"Alta",IF(OR(F30>=5000000,I30>=0.5),"Média","Normal")) -> Normal | R30: =IF(E30="Proposta aprovada","Fechado ganho",IF(E30="Perdida","Fechado perdido","Aberto")) -> Aberto
A31: 31 | B31: 46209 | C31: BCGA | D31: Fornecimento de Lenços e gravatas | E31: Perdida | F31: 9095000 | H31: 9095000 | I31: 0 | J31: Amélia Cassinda | K31: Apresentação de disponibilidade para futurod projectos | L31: 46240 | M31: Proposta rejeitada, por causa do tempo de produção e pelo fornecedor não ter o mesmo tecido | N31: =IF(B31="","",TODAY()-B31) -> 30 | O31: =F31*I31 -> 0 | P31: C | Q31: =IF(OR(F31>=50000000,I31>=0.75),"Alta",IF(OR(F31>=5000000,I31>=0.5),"Média","Normal")) -> Média | R31: =IF(E31="Proposta aprovada","Fechado ganho",IF(E31="Perdida","Fechado perdido","Aberto")) -> Fechado perdido
A32: 32 | B32: 46206 | C32: BCGA | D32: Fornecimento de Fita Tulyy | E32: Perdida | F32: 2684700 | H32: 2684700 | I32: 0 | J32: Amélia Cassinda | K32: Apresentação de disponibilidade para futurod projectos | L32: 46240 | M32: Proposta reajustada por falta de amostras físicas | N32: =IF(B32="","",TODAY()-B32) -> 33 | O32: =F32*I32 -> 0 | P32: A | Q32: =IF(OR(F32>=50000000,I32>=0.75),"Alta",IF(OR(F32>=5000000,I32>=0.5),"Média","Normal")) -> Normal | R32: =IF(E32="Proposta aprovada","Fechado ganho",IF(E32="Perdida","Fechado perdido","Aberto")) -> Fechado perdido
A33: 33 | B33: 46182 | C33: SBM OFFSHORE | D33: Impressão de Autocolante | E33: Proposta aprovada | F33: 339150 | G33: 339150 | H33: 0 | I33: 1 | J33: Amélia Cassinda | K33: Entrega do material ao cliente | L33: 46240 | M33: O material está pronto para ser entregue | N33: =IF(B33="","",MAX(0,TODAY()-B33)) -> 57 | O33: =IF(OR(F33="",I33=""),"",F33*I33) -> 339150 | P33: A | Q33: Normal | R33: Fechado ganho
A34: 34 | B34: 46216 | C34: BCGA | D34: Fornecimento de Sacolas | E34: Proposta aprovada | F34: 3135000 | G34: 3135000 | H34: 0 | I34: 1 | J34: Amélia Cassinda | K34: Resolver os impasses dentro do processo | L34: 46240 | M34: Tivemos alguns constrangimentos durante o processo, mas já estão a ser resolvidos | N34: =IF(B34="","",MAX(0,TODAY()-B34)) -> 23 | O34: =IF(OR(F34="",I34=""),"",F34*I34) -> 3135000 | P34: A | Q34: Alta | R34: Fechado ganho
A35: 35 | B35: 46216 | C35: TREVOTECH | D35: Fornecimento de Polos | E35: Perdida | F35: 889200 | G35: 0 | H35: 889200 | I35: 0 | J35: Amélia Cassinda | K35: Desculpar-se com o cliente pelo constrangimento causado no processo | L35: 46240 | M35: Material produzido e entregue | N35: =IF(B35="","",MAX(0,TODAY()-B35)) -> 23 | O35: =IF(OR(F35="",I35=""),"",F35*I35) -> 0 | P35: C | Q35: Normal | R35: Fechado perdido
A36: 36 | B36: 46220 | C36: ANGOLACA | D36: Fornecimento de Materiais Diversos | E36: Proposta enviada | F36: 14248432 | G36: 0 | H36: 0 | I36: 0.5 | J36: Amélia Cassinda | K36: Contactar a cliente para agendar uma reunião | L36: 46240 | M36: Proposta remetida para avaliação | N36: =IF(B36="","",MAX(0,TODAY()-B36)) -> 19 | O36: =IF(OR(F36="",I36=""),"",F36*I36) -> 7124216.2 | P36: C | Q36: Média | R36: Aberto
A37: 37 | B37: 46217 | C37: DUBAI INVESTIMETS | D37: Fornecimento de Garrafas Térmicas | E37: Proposta enviada | F37: 29724360 | G37: 0 | H37: 0 | I37: 0.4 | J37: Amélia Cassinda | K37: Avaliar a possibilidade de dar um desconto | L37: 46240 | M37: Proposta remetida para avaliação | N37: =IF(B37="","",MAX(0,TODAY()-B37)) -> 22 | O37: =IF(OR(F37="",I37=""),"",F37*I37) -> 11889744 | P37: C | Q37: Média | R37: Aberto
A38: 38 | B38: 46220 | C38: FADA | D38: Fornecimento de Brindes | E38: Proposta enviada | F38: 3583000 | G38: 0 | H38: 0 | I38: 0.4 | J38: Amélia Cassinda | K38: Solicitar o ponto de situação da proposta | L38: 46240 | M38: Proposta remetida para avaliação | N38: =IF(B38="","",MAX(0,TODAY()-B38)) -> 19 | O38: =IF(OR(F38="",I38=""),"",F38*I38) -> 1433200 | P38: B | Q38: Média | R38: Aberto
A39: 39 | B39: 46227 | C39: SANLAMALLIAZ | D39: Fornecimento de letras em 3D | E39: Proposta enviada | F39: 4008312 | G39: 0 | H39: 0 | I39: 0.5 | J39: Amélia Cassinda | K39: Solicitar um feedback do orçamento | L39: 46240 | M39: As propostas ainda estão a ser analisadas | N39: =IF(B39="","",MAX(0,TODAY()-B39)) -> 12 | O39: =IF(OR(F39="",I39=""),"",F39*I39) -> 2004156 | P39: A | Q39: Normal | R39: Aberto
A40: 40 | B40: 46225 | C40: CLINICA SAGRADA ESPERANÇA | D40: Fornecimento e aplicação de vinil fosco | E40: Proposta aprovada | F40: 3975230 | G40: 3975230 | H40: 0 | I40: 1 | J40: Amélia Cassinda | K40: Manter o contacto com o cliente para gerar novos negócios | L40: 46240 | M40: O processo de montagem foi concluído | N40: =IF(B40="","",MAX(0,TODAY()-B40)) -> 14 | O40: =IF(OR(F40="",I40=""),"",F40*I40) -> 3975230 | P40: C | Q40: Normal | R40: Aberto
...

Sheet KPIs_Comerciais
A1: KPIs AUTOMÁTICOS POR COMERCIAL
A4: Comercial | B4: N.º propostas | C4: Volume proposto | D4: Volume aprovado | E4: Volume perdido | F4: Pipeline ponderado | G4: Ticket médio | H4: Taxa conversão | I4: N.º aprovadas | J4: N.º abertas | K4: Contactos próximos 7 dias | L4: Negócios alta prioridade | M4: Desempenho
A5: Amélia Cassinda | B5: =COUNTIF(Pipeline!$J$2:$J$111,A5) -> 23 | C5: =SUMIF(Pipeline!$J$2:$J$111,A5,Pipeline!$F$2:$F$111) -> 1.9626971e+08 | D5: =SUMIF(Pipeline!$J$2:$J$111,A5,Pipeline!$G$2:$G$111) -> 9641030 | E5: =SUMIF(Pipeline!$J$2:$J$111,A5,Pipeline!$H$2:$H$111) -> 12668900 | F5: =SUMIF(Pipeline!$J$2:$J$111,A5,Pipeline!$O$2:$O$111) -> 82964376 | G5: =IF(B5=0,0,C5/B5) -> 8533465.8 | H5: =IF(C5=0,0,D5/C5) -> 0.049121333 | I5: =COUNTIFS(Pipeline!$J$2:$J$111,A5,Pipeline!$E$2:$E$111,"Proposta aprovada") -> 5 | J5: =COUNTIFS(Pipeline!$J$2:$J$111,A5,Pipeline!$R$2:$R$111,"Aberto") -> 13 | K5: =COUNTIFS(Pipeline!$J$2:$J$111,A5,Pipeline!$L$2:$L$111,">="&TODAY(),Pipeline!$L$2:$L$111,"<="&TODAY()+7) -> 23 | L5: =COUNTIFS(Pipeline!$J$2:$J$111,A5,Pipeline!$Q$2:$Q$111,"Alta") -> 4 | M5: =IF(H5>=0.2,"Excelente",IF(H5>=0.1,"Bom",IF(H5>0,"Baixo","Crítico"))) -> Baixo
A6: David Guedes | B6: =COUNTIF(Pipeline!$J$2:$J$111,A6) -> 14 | C6: =SUMIF(Pipeline!$J$2:$J$111,A6,Pipeline!$F$2:$F$111) -> 62249844 | D6: =SUMIF(Pipeline!$J$2:$J$111,A6,Pipeline!$G$2:$G$111) -> 13754328 | E6: =SUMIF(Pipeline!$J$2:$J$111,A6,Pipeline!$H$2:$H$111) -> 4206170 | F6: =SUMIF(Pipeline!$J$2:$J$111,A6,Pipeline!$O$2:$O$111) -> 28629859 | G6: =IF(B6=0,0,C6/B6) -> 4446417.4 | H6: =IF(C6=0,0,D6/C6) -> 0.22095361 | I6: =COUNTIFS(Pipeline!$J$2:$J$111,A6,Pipeline!$E$2:$E$111,"Proposta aprovada") -> 3 | J6: =COUNTIFS(Pipeline!$J$2:$J$111,A6,Pipeline!$R$2:$R$111,"Aberto") -> 11 | K6: =COUNTIFS(Pipeline!$J$2:$J$111,A6,Pipeline!$L$2:$L$111,">="&TODAY(),Pipeline!$L$2:$L$111,"<="&TODAY()+7) -> 13 | L6: =COUNTIFS(Pipeline!$J$2:$J$111,A6,Pipeline!$Q$2:$Q$111,"Alta") -> 9 | M6: =IF(H6>=0.2,"Excelente",IF(H6>=0.1,"Bom",IF(H6>0,"Baixo","Crítico"))) -> Excelente
A7: Ilídio Pedro | B7: =COUNTIF(Pipeline!$J$2:$J$111,A7) -> 10 | C7: =SUMIF(Pipeline!$J$2:$J$111,A7,Pipeline!$F$2:$F$111) -> 42023854 | D7: =SUMIF(Pipeline!$J$2:$J$111,A7,Pipeline!$G$2:$G$111) -> 12876300 | E7: =SUMIF(Pipeline!$J$2:$J$111,A7,Pipeline!$H$2:$H$111) -> 3243300 | F7: =SUMIF(Pipeline!$J$2:$J$111,A7,Pipeline!$O$2:$O$111) -> 19174244 | G7: =IF(B7=0,0,C7/B7) -> 4202385.4 | H7: =IF(C7=0,0,D7/C7) -> 0.30640455 | I7: =COUNTIFS(Pipeline!$J$2:$J$111,A7,Pipeline!$E$2:$E$111,"Proposta aprovada") -> 5 | J7: =COUNTIFS(Pipeline!$J$2:$J$111,A7,Pipeline!$R$2:$R$111,"Aberto") -> 4 | K7: =COUNTIFS(Pipeline!$J$2:$J$111,A7,Pipeline!$L$2:$L$111,">="&TODAY(),Pipeline!$L$2:$L$111,"<="&TODAY()+7) -> 10 | L7: =COUNTIFS(Pipeline!$J$2:$J$111,A7,Pipeline!$Q$2:$Q$111,"Alta") -> 3 | M7: =IF(H7>=0.2,"Excelente",IF(H7>=0.1,"Bom",IF(H7>0,"Baixo","Crítico"))) -> Excelente
A8: Fernando Leite | B8: =COUNTIF(Pipeline!$J$2:$J$111,A8) -> 12 | C8: =SUMIF(Pipeline!$J$2:$J$111,A8,Pipeline!$F$2:$F$111) -> 26970129 | D8: =SUMIF(Pipeline!$J$2:$J$111,A8,Pipeline!$G$2:$G$111) -> 1863909 | E8: =SUMIF(Pipeline!$J$2:$J$111,A8,Pipeline!$H$2:$H$111) -> 9741015 | F8: =SUMIF(Pipeline!$J$2:$J$111,A8,Pipeline!$O$2:$O$111) -> 8238410.5 | G8: =IF(B8=0,0,C8/B8) -> 2247510.8 | H8: =IF(C8=0,0,D8/C8) -> 0.069110126 | I8: =COUNTIFS(Pipeline!$J$2:$J$111,A8,Pipeline!$E$2:$E$111,"Proposta aprovada") -> 5 | J8: =COUNTIFS(Pipeline!$J$2:$J$111,A8,Pipeline!$R$2:$R$111,"Aberto") -> 5 | K8: =COUNTIFS(Pipeline!$J$2:$J$111,A8,Pipeline!$L$2:$L$111,">="&TODAY(),Pipeline!$L$2:$L$111,"<="&TODAY()+7) -> 12 | L8: =COUNTIFS(Pipeline!$J$2:$J$111,A8,Pipeline!$Q$2:$Q$111,"Alta") -> 4 | M8: =IF(H8>=0.2,"Excelente",IF(H8>=0.1,"Bom",IF(H8>0,"Baixo","Crítico"))) -> Baixo
A9: Luísa Baltazar | B9: =COUNTIF(Pipeline!$J$2:$J$111,A9) -> 25 | C9: =SUMIF(Pipeline!$J$2:$J$111,A9,Pipeline!$F$2:$F$111) -> 2.9544381e+08 | D9: =SUMIF(Pipeline!$J$2:$J$115,A9,Pipeline!$G$2:$G$115) -> 30159800 | E9: =SUMIF(Pipeline!$J$2:$J$111,A9,Pipeline!$H$2:$H$111) -> 6222120 | F9: =SUMIF(Pipeline!$J$2:$J$111,A9,Pipeline!$O$2:$O$111) -> 49126134 | G9: =IF(B9=0,0,C9/B9) -> 11817752 | H9: =IF(C9=0,0,D9/C9) -> 0.10208303 | I9: =COUNTIFS(Pipeline!$J$2:$J$111,A9,Pipeline!$E$2:$E$111,"Proposta aprovada") -> 9 | J9: =COUNTIFS(Pipeline!$J$2:$J$111,A9,Pipeline!$R$2:$R$111,"Aberto") -> 13 | K9: =COUNTIFS(Pipeline!$J$2:$J$111,A9,Pipeline!$L$2:$L$111,">="&TODAY(),Pipeline!$L$2:$L$111,"<="&TODAY()+7) -> 25 | L9: =COUNTIFS(Pipeline!$J$2:$J$111,A9,Pipeline!$Q$2:$Q$111,"Alta") -> 14 | M9: =IF(H9>=0.2,"Excelente",IF(H9>=0.1,"Bom",IF(H9>0,"Baixo","Crítico"))) -> Bom
A10: Marta de Oliveira | B10: =COUNTIF(Pipeline!$J$2:$J$111,A10) -> 18 | C10: =SUMIF(Pipeline!$J$2:$J$111,A10,Pipeline!$F$2:$F$111) -> 1.1112597e+08 | D10: =SUMIF(Pipeline!$J$2:$J$111,A10,Pipeline!$G$2:$G$111) -> 32203170 | E10: =SUMIF(Pipeline!$J$2:$J$111,A10,Pipeline!$H$2:$H$111) -> 12398175 | F10: =SUMIF(Pipeline!$J$2:$J$111,A10,Pipeline!$O$2:$O$111) -> 58892478 | G10: =IF(B10=0,0,C10/B10) -> 6173664.9 | H10: =IF(C10=0,0,D10/C10) -> 0.28978978 | I10: =COUNTIFS(Pipeline!$J$2:$J$111,A10,Pipeline!$E$2:$E$111,"Proposta aprovada") -> 8 | J10: =COUNTIFS(Pipeline!$J$2:$J$111,A10,Pipeline!$R$2:$R$111,"Aberto") -> 9 | K10: =COUNTIFS(Pipeline!$J$2:$J$111,A10,Pipeline!$L$2:$L$111,">="&TODAY(),Pipeline!$L$2:$L$111,"<="&TODAY()+7) -> 18 | L10: =COUNTIFS(Pipeline!$J$2:$J$111,A10,Pipeline!$Q$2:$Q$111,"Alta") -> 8 | M10: =IF(H10>=0.2,"Excelente",IF(H10>=0.1,"Bom",IF(H10>0,"Baixo","Crítico"))) -> Excelente
A11: José Neto | B11: =COUNTIF(Pipeline!$J$2:$J$111,A11) -> 8 | C11: =SUMIF(Pipeline!$J$2:$J$111,A11,Pipeline!$F$2:$F$111) -> 39749380 | D11: =SUMIF(Pipeline!$J$2:$J$111,A11,Pipeline!$G$2:$G$111) -> 855000 | E11: =SUMIF(Pipeline!$J$2:$J$111,A11,Pipeline!$H$2:$H$111) -> 881448 | F11: =SUMIF(Pipeline!$J$2:$J$111,A11,Pipeline!$O$2:$O$111) -> 18661541 | G11: =IF(B11=0,0,C11/B11) -> 4968672.5 | H11: =IF(C11=0,0,D11/C11) -> 0.021509769 | I11: =COUNTIFS(Pipeline!$J$2:$J$111,A11,Pipeline!$E$2:$E$111,"Proposta aprovada") -> 1 | J11: =COUNTIFS(Pipeline!$J$2:$J$111,A11,Pipeline!$R$2:$R$111,"Aberto") -> 7 | K11: =COUNTIFS(Pipeline!$J$2:$J$111,A11,Pipeline!$L$2:$L$111,">="&TODAY(),Pipeline!$L$2:$L$111,"<="&TODAY()+7) -> 8 | L11: =COUNTIFS(Pipeline!$J$2:$J$111,A11,Pipeline!$Q$2:$Q$111,"Alta") -> 1 | M11: =IF(H11>=0.2,"Excelente",IF(H11>=0.1,"Bom",IF(H11>0,"Baixo","Crítico"))) -> Baixo
A12: TOTAL EQUIPA | B12: =SUM(B5:B11) -> 110 | C12: =SUM(C5:C11) -> 7.738327e+08 | D12: =SUM(D5:D11) -> 101353537 | E12: =SUM(E5:E11) -> 49361128 | F12: =SUM(F5:F11) -> 2.1036587e+08 | G12: =IF(B12=0,0,C12/B12) -> 7034842.7 | H12: =IF(C12=0,0,D12/C12) -> 0.13097603 | I12: =SUM(I5:I11) -> 36 | J12: =SUM(J5:J11) -> 62 | K12: =SUM(K5:K11) -> 109 | L12: =SUM(L5:L11) -> 43 | M12: Síntese

Sheet Comparativo_Semanas
A1: COMPARATIVO DAS 2 ÚLTIMAS SEMANAS
A4: Descrição | B4: 01 - 30 Junho 2026 | C4: 01 – 31 Julho 2026 | D4: Variação
A5: N.º de pedidos (declarado) | B5: 113 | C5: 110 | D5: =IF(B5=0,0,C5/B5-1) -> -0.026548673
A6: N.º de linhas no pipeline | B6: 113 | C6: 111 | D6: =IF(B6=0,0,C6/B6-1) -> -0.017699115
A7: Total de propostas | B7: 7.5484513e+08 | C7: 7.738327e+08 | D7: =IF(B7=0,0,C7/B7-1) -> 0.025154264
A8: Total aprovado | B8: 57094130 | C8: 101353537 | D8: =IF(B8=0,0,C8/B8-1) -> 0.77520067
A9: Total perdido | B9: 26060058 | C9: 49361128 | D9: =IF(B9=0,0,C9/B9-1) -> 0.89412962
A10: Taxa de conversão | B10: =B8/B7 -> 0.075636879 | C10: =C8/C7 -> 0.13097603 | D10: =D8/D7 -> 30.817863

Sheet Dashboard
A1: DASHBOARD EXECUTIVO DO CRM
A4: N.º registos | C4: Volume proposto | E4: Volume aprovado | G4: Taxa conversão
A5: =COUNTA(Pipeline!$A$2:$A$102) -> 101 | C5: =SUM(Pipeline!$F$2:$F$111) -> 7.738327e+08 | E5: =SUM(Pipeline!$G$2:$G$111) -> 101353537 | G5: =IF(C5=0,0,E5/C5) -> 0.13097603
A8: Pipeline ponderado | C8: Probabilidade média | E8: Alta prioridade | G8: Contactos próximos 7 dias
A9: =SUM(Pipeline!$O$2:$O$111) -> 3.7065543e+08 | C9: =AVERAGE(Pipeline!$I$2:$I$111) -> 0.57 | E9: =COUNTIF(Pipeline!$Q$2:$Q$111,"Alta") -> 43 | G9: =COUNTIFS(Pipeline!$L$2:$L$111,">="&TODAY(),Pipeline!$L$2:$L$111,"<="&TODAY()+7) -> 109
A12: Leitura automática: o CRM calcula o valor ponderado por oportunidade, classifica a prioridade, controla o follow-up e apresenta o desempenho de cada comercial. Actualize apenas as células de registo e deixe as colunas de fórmula intactas.
J13: Estado | K13: N.º
J14: Proposta enviada | K14: =COUNTIF(Pipeline!$E$2:$E$111,J14) -> 52
J15: Proposta em negociação | K15: =COUNTIF(Pipeline!$E$2:$E$111,J15) -> 11
J16: Proposta aprovada | K16: =COUNTIF(Pipeline!$E$2:$E$111,J16) -> 36
J17: Perdida | K17: =COUNTIF(Pipeline!$E$2:$E$111,J17) -> 11
J20: Comercial | K20: Volume | L20: Aprovado | M20: Ponderado
J21: =KPIs_Comerciais!A5 -> Amélia Cassinda | K21: =KPIs_Comerciais!C5 -> 1.9626971e+08 | L21: =KPIs_Comerciais!D5 -> 9641030 | M21: =KPIs_Comerciais!F5 -> 82964376
J22: =KPIs_Comerciais!A6 -> David Guedes | K22: =KPIs_Comerciais!C6 -> 62249844 | L22: =KPIs_Comerciais!D6 -> 13754328 | M22: =KPIs_Comerciais!F6 -> 28629859
J23: =KPIs_Comerciais!A7 -> Ilídio Pedro | K23: =KPIs_Comerciais!C7 -> 42023854 | L23: =KPIs_Comerciais!D7 -> 12876300 | M23: =KPIs_Comerciais!F7 -> 19174244
J24: =KPIs_Comerciais!A8 -> Fernando Leite | K24: =KPIs_Comerciais!C8 -> 26970129 | L24: =KPIs_Comerciais!D8 -> 1863909 | M24: =KPIs_Comerciais!F8 -> 8238410.5
J25: =KPIs_Comerciais!A9 -> Luísa Baltazar | K25: =KPIs_Comerciais!C9 -> 2.9544381e+08 | L25: =KPIs_Comerciais!D9 -> 30159800 | M25: 49126134
J26: =KPIs_Comerciais!A10 -> Marta de Oliveira | K26: =KPIs_Comerciais!C10 -> 1.1112597e+08 | L26: =KPIs_Comerciais!D10 -> 32203170 | M26: =KPIs_Comerciais!F10 -> 58892478
J27: =KPIs_Comerciais!A11 -> José Neto | K27: =KPIs_Comerciais!C11 -> 39749380 | L27: =KPIs_Comerciais!D11 -> 855000 | M27: =KPIs_Comerciais!F11 -> 18661541
